{
 "cells": [
  {
   "cell_type": "code",
   "execution_count": null,
   "id": "18738ec1",
   "metadata": {},
   "outputs": [
    {
     "ename": "",
     "evalue": "",
     "output_type": "error",
     "traceback": [
      "\u001b[1;31mFailed to start the Kernel. \n",
      "\u001b[1;31mUnable to start Kernel 'anaconda3 (Python 3.9.16)' due to connection timeout. \n",
      "\u001b[1;31mView Jupyter <a href='command:jupyter.viewOutput'>log</a> for further details."
     ]
    }
   ],
   "source": [
    "import tensorflow as tf\n",
    "from tensorflow import keras\n",
    "from keras.utils import image_dataset_from_directory\n",
    "from tensorflow.keras import layers"
   ]
  },
  {
   "cell_type": "code",
   "execution_count": null,
   "id": "189f5e77",
   "metadata": {},
   "outputs": [
    {
     "ename": "",
     "evalue": "",
     "output_type": "error",
     "traceback": [
      "\u001b[1;31mFailed to start the Kernel. \n",
      "\u001b[1;31mUnable to start Kernel 'anaconda3 (Python 3.9.16)' due to connection timeout. \n",
      "\u001b[1;31mView Jupyter <a href='command:jupyter.viewOutput'>log</a> for further details."
     ]
    }
   ],
   "source": [
    "import os\n",
    "\n",
    "train=image_dataset_from_directory(\"C:\\Users\\User\\Downloads\\Img_dataset\\train\")"
   ]
  },
  {
   "cell_type": "code",
   "execution_count": null,
   "id": "dded51a9",
   "metadata": {},
   "outputs": [
    {
     "ename": "",
     "evalue": "",
     "output_type": "error",
     "traceback": [
      "\u001b[1;31mFailed to start the Kernel. \n",
      "\u001b[1;31mUnable to start Kernel 'anaconda3 (Python 3.9.16)' due to connection timeout. \n",
      "\u001b[1;31mView Jupyter <a href='command:jupyter.viewOutput'>log</a> for further details."
     ]
    }
   ],
   "source": [
    "test=keras.utils.text_dataset_from_directory(\"~/downloads/finance.csv\")"
   ]
  },
  {
   "cell_type": "code",
   "execution_count": null,
   "id": "a828490f",
   "metadata": {},
   "outputs": [
    {
     "ename": "",
     "evalue": "",
     "output_type": "error",
     "traceback": [
      "\u001b[1;31mFailed to start the Kernel. \n",
      "\u001b[1;31mUnable to start Kernel 'anaconda3 (Python 3.9.16)' due to connection timeout. \n",
      "\u001b[1;31mView Jupyter <a href='command:jupyter.viewOutput'>log</a> for further details."
     ]
    }
   ],
   "source": []
  }
 ],
 "metadata": {
  "kernelspec": {
   "display_name": "Python 3 (ipykernel)",
   "language": "python",
   "name": "python3"
  },
  "language_info": {
   "codemirror_mode": {
    "name": "ipython",
    "version": 3
   },
   "file_extension": ".py",
   "mimetype": "text/x-python",
   "name": "python",
   "nbconvert_exporter": "python",
   "pygments_lexer": "ipython3",
   "version": "3.9.16"
  }
 },
 "nbformat": 4,
 "nbformat_minor": 5
}
